Workbook

Sheet Portfolio
A1: Date | B1: Total Value | C1: Portf. Close | D1: Cash of the Portfolio (Dividends) | E1: Total Day CF | F1: HYG Position | G1: HYG Dividends | H1: LQD Position | I1: LQD Dividends | J1: SPY Position | K1: SPY Dividends | L1: TLT Position | M1: TLT Dividends
A2: 46022 | B2: =C2+D2 -> 26564.026 | C2: =F2+H2+J2+L2 -> 21097.148 | D2: =D3+E2 -> 5466.8783 | E2: =G2+I2+K2+M2 -> 5.652794 | F2: =VLOOKUP(A2,'Adj HYG'!$A$1:$L$1456,12,FALSE)*100 -> 8061.1877 | G2: =VLOOKUP(A2,'HYG DVD'!$A$1:$E$1256,5,FALSE) -> 1.8125112 | H2: =VLOOKUP(A2,'Adj LQD'!$A$1:$L$1456,12,FALSE)*200 -> 22033.844 | I2: =VLOOKUP(A2,'LQD DVD'!$A$1:$E$1256,5,FALSE) -> 4.1566991 | J2: =VLOOKUP(A2,'Adj SPY'!$A$1:$L$1456,12,FALSE)*-10 -> -6818.8836 | K2: =VLOOKUP(A2,'SPY DVD'!$A$1:$E$1256,5,FALSE) -> -0.31641629 | L2: =VLOOKUP(A2,'Adj TLT'!$A$1:$L$1456,12,FALSE)*-25 -> -2179 | M2: =IFERROR(VLOOKUP(A2,'TLT DVD'!$A$1:$E$1249,5,FALSE),0) -> 0
A3: 46021 | B3: =C3+D3 -> 26591.973 | C3: =F3+H3+J3+L3 -> 21130.748 | D3: =D4+E3 -> 5461.2255 | E3: =G3+I3+K3+M3 -> 5.6528537 | F3: =VLOOKUP(A3,'Adj HYG'!$A$1:$L$1456,12,FALSE)*100 -> 8069.1877 | G3: =VLOOKUP(A3,'HYG DVD'!$A$1:$E$1256,5,FALSE) -> 1.812484 | H3: =VLOOKUP(A3,'Adj LQD'!$A$1:$L$1456,12,FALSE)*200 -> 22127.844 | I3: =VLOOKUP(A3,'LQD DVD'!$A$1:$E$1256,5,FALSE) -> 4.156776 | J3: =VLOOKUP(A3,'Adj SPY'!$A$1:$L$1456,12,FALSE)*-10 -> -6869.7836 | K3: =VLOOKUP(A3,'SPY DVD'!$A$1:$E$1256,5,FALSE) -> -0.31640627 | L3: =VLOOKUP(A3,'Adj TLT'!$A$1:$L$1456,12,FALSE)*-25 -> -2196.5 | M3: =IFERROR(VLOOKUP(A3,'TLT DVD'!$A$1:$E$1249,5,FALSE),0) -> 0
A4: 46020 | B4: =C4+D4 -> 26590.67 | C4: =F4+H4+J4+L4 -> 21135.098 | D4: =D5+E4 -> 5455.5727 | E4: =G4+I4+K4+M4 -> 5.6528355 | F4: =VLOOKUP(A4,'Adj HYG'!$A$1:$L$1456,12,FALSE)*100 -> 8061.1877 | G4: =VLOOKUP(A4,'HYG DVD'!$A$1:$E$1256,5,FALSE) -> 1.8125112 | H4: =VLOOKUP(A4,'Adj LQD'!$A$1:$L$1456,12,FALSE)*200 -> 22153.844 | I4: =VLOOKUP(A4,'LQD DVD'!$A$1:$E$1256,5,FALSE) -> 4.1567353 | J4: =VLOOKUP(A4,'Adj SPY'!$A$1:$L$1456,12,FALSE)*-10 -> -6878.1836 | K4: =VLOOKUP(A4,'SPY DVD'!$A$1:$E$1256,5,FALSE) -> -0.316411 | L4: =VLOOKUP(A4,'Adj TLT'!$A$1:$L$1456,12,FALSE)*-25 -> -2201.75 | M4: =IFERROR(VLOOKUP(A4,'TLT DVD'!$A$1:$E$1249,5,FALSE),0) -> 0
A5: 46017 | B5: =C5+D5 -> 26536.075 | C5: =F5+H5+J5+L5 -> 21086.155 | D5: =D6+E5 -> 5449.9198 | E5: =G5+I5+K5+M5 -> 5.2449237 | F5: =VLOOKUP(A5,'Adj HYG'!$A$1:$L$1456,12,FALSE)*100 -> 8058.1877 | G5: =VLOOKUP(A5,'HYG DVD'!$A$1:$E$1256,5,FALSE) -> 1.8125085 | H5: =VLOOKUP(A5,'Adj LQD'!$A$1:$L$1456,12,FALSE)*200 -> 22123.844 | I5: =VLOOKUP(A5,'LQD DVD'!$A$1:$E$1256,5,FALSE) -> 4.1567272 | J5: =VLOOKUP(A5,'Adj SPY'!$A$1:$L$1456,12,FALSE)*-10 -> -6902.7836 | K5: =VLOOKUP(A5,'SPY DVD'!$A$1:$E$1256,5,FALSE) -> -0.31641948 | L5: =VLOOKUP(A5,'Adj TLT'!$A$1:$L$1456,12,FALSE)*-25 -> -2193.0924 | M5: =IFERROR(VLOOKUP(A5,'TLT DVD'!$A$1:$E$1249,5,FALSE),0) -> -0.40789255
A6: 46015 | B6: =C6+D6 -> 26528.88 | C6: =F6+H6+J6+L6 -> 21084.205 | D6: =D7+E6 -> 5444.6749 | E6: =G6+I6+K6+M6 -> 5.2486454 | F6: =VLOOKUP(A6,'Adj HYG'!$A$1:$L$1456,12,FALSE)*100 -> 8062.1877 | G6: =VLOOKUP(A6,'HYG DVD'!$A$1:$E$1256,5,FALSE) -> 1.81248 | H6: =VLOOKUP(A6,'Adj LQD'!$A$1:$L$1456,12,FALSE)*200 -> 22125.844 | I6: =VLOOKUP(A6,'LQD DVD'!$A$1:$E$1256,5,FALSE) -> 4.1567517 | J6: =VLOOKUP(A6,'Adj SPY'!$A$1:$L$1456,12,FALSE)*-10 -> -6903.4836 | K6: =VLOOKUP(A6,'SPY DVD'!$A$1:$E$1256,5,FALSE) -> -0.31639677 | L6: =VLOOKUP(A6,'Adj TLT'!$A$1:$L$1456,12,FALSE)*-25 -> -2200.3424 | M6: =IFERROR(VLOOKUP(A6,'TLT DVD'!$A$1:$E$1249,5,FALSE),0) -> -0.40418952
A7: 46014 | B7: =C7+D7 -> 26460.082 | C7: =F7+H7+J7+L7 -> 21020.655 | D7: =D8+E7 -> 5439.4263 | E7: =G7+I7+K7+M7 -> 5.2453898 | F7: =VLOOKUP(A7,'Adj HYG'!$A$1:$L$1456,12,FALSE)*100 -> 8047.1877 | G7: =VLOOKUP(A7,'HYG DVD'!$A$1:$E$1256,5,FALSE) -> 1.8124943 | H7: =VLOOKUP(A7,'Adj LQD'!$A$1:$L$1456,12,FALSE)*200 -> 22039.844 | I7: =VLOOKUP(A7,'LQD DVD'!$A$1:$E$1256,5,FALSE) -> 4.1567811 | J7: =VLOOKUP(A7,'Adj SPY'!$A$1:$L$1456,12,FALSE)*-10 -> -6879.2836 | K7: =VLOOKUP(A7,'SPY DVD'!$A$1:$E$1256,5,FALSE) -> -0.316407 | L7: =VLOOKUP(A7,'Adj TLT'!$A$1:$L$1456,12,FALSE)*-25 -> -2187.0924 | M7: =IFERROR(VLOOKUP(A7,'TLT DVD'!$A$1:$E$1249,5,FALSE),0) -> -0.40747857
A8: 46013 | B8: =C8+D8 -> 26461.636 | C8: =F8+H8+J8+L8 -> 21027.455 | D8: =D9+E8 -> 5434.1809 | E8: =G8+I8+K8+M8 -> 5.2466931 | F8: =VLOOKUP(A8,'Adj HYG'!$A$1:$L$1456,12,FALSE)*100 -> 8041.1877 | G8: =VLOOKUP(A8,'HYG DVD'!$A$1:$E$1256,5,FALSE) -> 1.8124837 | H8: =VLOOKUP(A8,'Adj LQD'!$A$1:$L$1456,12,FALSE)*200 -> 22017.844 | I8: =VLOOKUP(A8,'LQD DVD'!$A$1:$E$1256,5,FALSE) -> 4.1567399 | J8: =VLOOKUP(A8,'Adj SPY'!$A$1:$L$1456,12,FALSE)*-10 -> -6847.9836 | K8: =VLOOKUP(A8,'SPY DVD'!$A$1:$E$1256,5,FALSE) -> -0.31640777 | L8: =VLOOKUP(A8,'Adj TLT'!$A$1:$L$1456,12,FALSE)*-25 -> -2183.5924 | M8: =IFERROR(VLOOKUP(A8,'TLT DVD'!$A$1:$E$1249,5,FALSE),0) -> -0.40612273
A9: 46010 | B9: =C9+D9 -> 26491.04 | C9: =F9+H9+J9+L9 -> 21062.105 | D9: =D10+E9 -> 5428.9342 | E9: =G9+I9+K9+M9 -> 5.2469412 | F9: =VLOOKUP(A9,'Adj HYG'!$A$1:$L$1456,12,FALSE)*100 -> 8034.1877 | G9: =VLOOKUP(A9,'HYG DVD'!$A$1:$E$1256,5,FALSE) -> 1.8125007 | H9: =VLOOKUP(A9,'Adj LQD'!$A$1:$L$1456,12,FALSE)*200 -> 22021.844 | I9: =VLOOKUP(A9,'LQD DVD'!$A$1:$E$1256,5,FALSE) -> 4.1567083 | J9: =VLOOKUP(A9,'Adj SPY'!$A$1:$L$1456,12,FALSE)*-10 -> -6805.5836 | K9: =VLOOKUP(A9,'SPY DVD'!$A$1:$E$1256,5,FALSE) -> -0.31642033 | L9: =VLOOKUP(A9,'Adj TLT'!$A$1:$L$1456,12,FALSE)*-25 -> -2188.3424 | M9: =IFERROR(VLOOKUP(A9,'TLT DVD'!$A$1:$E$1249,5,FALSE),0) -> -0.4058474
A10: 46009 | B10: =C10+D10 -> 26696.243 | C10: =F10+H10+J10+L10 -> 21272.555 | D10: =D11+E10 -> 5423.6872 | E10: =G10+I10+K10+M10 -> 5.2467696 | F10: =VLOOKUP(A10,'Adj HYG'!$A$1:$L$1456,12,FALSE)*100 -> 8076.1877 | G10: =VLOOKUP(A10,'HYG DVD'!$A$1:$E$1256,5,FALSE) -> 1.8124852 | H10: =VLOOKUP(A10,'Adj LQD'!$A$1:$L$1456,12,FALSE)*200 -> 22165.844 | I10: =VLOOKUP(A10,'LQD DVD'!$A$1:$E$1256,5,FALSE) -> 4.156699 | J10: =VLOOKUP(A10,'Adj SPY'!$A$1:$L$1456,12,FALSE)*-10 -> -6764.3836 | K10: =VLOOKUP(A10,'SPY DVD'!$A$1:$E$1256,5,FALSE) -> -0.31641079 | L10: =VLOOKUP(A10,'Adj TLT'!$A$1:$L$1456,12,FALSE)*-25 -> -2205.0924 | M10: =IFERROR(VLOOKUP(A10,'TLT DVD'!$A$1:$E$1249,5,FALSE),0) -> -0.40600385
A11: 46008 | B11: =C11+D11 -> 26646.391 | C11: =F11+H11+J11+L11 -> 21227.95 | D11: =D12+E11 -> 5418.4405 | E11: =G11+I11+K11+M11 -> 5.0489353 | F11: =VLOOKUP(A11,'Adj HYG'!$A$1:$L$1456,12,FALSE)*100 -> 8054.2156 | G11: =VLOOKUP(A11,'HYG DVD'!$A$1:$E$1256,5,FALSE) -> 1.7845958 | H11: =VLOOKUP(A11,'Adj LQD'!$A$1:$L$1456,12,FALSE)*200 -> 22082.062 | I11: =VLOOKUP(A11,'LQD DVD'!$A$1:$E$1256,5,FALSE) -> 3.9378812 | J11: =VLOOKUP(A11,'Adj SPY'!$A$1:$L$1456,12,FALSE)*-10 -> -6713.7094 | K11: =VLOOKUP(A11,'SPY DVD'!$A$1:$E$1256,5,FALSE) -> -0.29064693 | L11: =VLOOKUP(A11,'Adj TLT'!$A$1:$L$1456,12,FALSE)*-25 -> -2194.6183 | M11: =IFERROR(VLOOKUP(A11,'TLT DVD'!$A$1:$E$1249,5,FALSE),0) -> -0.38289481
A12: 46007 | B12: =C12+D12 -> 26598.642 | C12: =F12+H12+J12+L12 -> 21185.25 | D12: =D13+E12 -> 5413.3915 | E12: =G12+I12+K12+M12 -> 5.0507916 | F12: =VLOOKUP(A12,'Adj HYG'!$A$1:$L$1456,12,FALSE)*100 -> 8064.2156 | G12: =VLOOKUP(A12,'HYG DVD'!$A$1:$E$1256,5,FALSE) -> 1.7846025 | H12: =VLOOKUP(A12,'Adj LQD'!$A$1:$L$1456,12,FALSE)*200 -> 22106.062 | I12: =VLOOKUP(A12,'LQD DVD'!$A$1:$E$1256,5,FALSE) -> 3.9379489 | J12: =VLOOKUP(A12,'Adj SPY'!$A$1:$L$1456,12,FALSE)*-10 -> -6788.4094 | K12: =VLOOKUP(A12,'SPY DVD'!$A$1:$E$1256,5,FALSE) -> -0.29064795 | L12: =VLOOKUP(A12,'Adj TLT'!$A$1:$L$1456,12,FALSE)*-25 -> -2196.6183 | M12: =IFERROR(VLOOKUP(A12,'TLT DVD'!$A$1:$E$1249,5,FALSE),0) -> -0.38111192
A13: 46006 | B13: =C13+D13 -> 26531.991 | C13: =F13+H13+J13+L13 -> 21123.65 | D13: =D14+E13 -> 5408.3407 | E13: =G13+I13+K13+M13 -> 5.0473637 | F13: =VLOOKUP(A13,'Adj HYG'!$A$1:$L$1456,12,FALSE)*100 -> 8059.2156 | G13: =VLOOKUP(A13,'HYG DVD'!$A$1:$E$1256,5,FALSE) -> 1.7846158 | H13: =VLOOKUP(A13,'Adj LQD'!$A$1:$L$1456,12,FALSE)*200 -> 22056.062 | I13: =VLOOKUP(A13,'LQD DVD'!$A$1:$E$1256,5,FALSE) -> 3.9378851 | J13: =VLOOKUP(A13,'Adj SPY'!$A$1:$L$1456,12,FALSE)*-10 -> -6807.0093 | K13: =VLOOKUP(A13,'SPY DVD'!$A$1:$E$1256,5,FALSE) -> -0.2906609 | L13: =VLOOKUP(A13,'Adj TLT'!$A$1:$L$1456,12,FALSE)*-25 -> -2184.6183 | M13: =IFERROR(VLOOKUP(A13,'TLT DVD'!$A$1:$E$1249,5,FALSE),0) -> -0.38447626
... A1250: 44208 | B1250: =C1250+D1250 -> 28237.48 | C1250: =F1250+H1250+J1250+L1250 -> 28229.619 | D1250: =D1251+E1250 -> 7.8604032 | E1250: =G1250+I1250+K1250+M1250 -> 3.9298216 | F1250: =VLOOKUP(A1250,'Adj HYG'!$A$1:$L$1456,12,FALSE)*100 -> 8699.2899 | G1250: =VLOOKUP(A1250,'HYG DVD'!$A$1:$E$1256,5,FALSE) -> 1.7102644 | H1250: =VLOOKUP(A1250,'Adj LQD'!$A$1:$L$1456,12,FALSE)*200 -> 27091.333 | I1250: =VLOOKUP(A1250,'LQD DVD'!$A$1:$E$1256,5,FALSE) -> 2.6667162 | J1250: =VLOOKUP(A1250,'Adj SPY'!$A$1:$L$1456,12,FALSE)*-10 -> -3787.4492 | K1250: =VLOOKUP(A1250,'SPY DVD'!$A$1:$E$1256,5,FALSE) -> -0.25079985 | L1250: =VLOOKUP(A1250,'Adj TLT'!$A$1:$L$1456,12,FALSE)*-25 -> -3773.5548 | M1250: =IFERROR(VLOOKUP(A1250,'TLT DVD'!$A$1:$E$1249,5,FALSE),0) -> -0.19635914
A1251: 44207 | B1251: =C1251+D1251 -> 28162.35 | C1251: =F1251+H1251+J1251+L1251 -> 28158.419 | D1251: =E1251 -> 3.9305816 | E1251: =G1251+I1251+K1251+M1251 -> 3.9305816 | F1251: =VLOOKUP(A1251,'Adj HYG'!$A$1:$L$1456,12,FALSE)*100 -> 8688.2899 | G1251: =VLOOKUP(A1251,'HYG DVD'!$A$1:$E$1256,5,FALSE) -> 1.7102403 | H1251: =VLOOKUP(A1251,'Adj LQD'!$A$1:$L$1456,12,FALSE)*200 -> 27033.333 | I1251: =VLOOKUP(A1251,'LQD DVD'!$A$1:$E$1256,5,FALSE) -> 2.6666937 | J1251: =VLOOKUP(A1251,'Adj SPY'!$A$1:$L$1456,12,FALSE)*-10 -> -3786.6492 | K1251: =VLOOKUP(A1251,'SPY DVD'!$A$1:$E$1256,5,FALSE) -> -0.25079196 | L1251: =VLOOKUP(A1251,'Adj TLT'!$A$1:$L$1456,12,FALSE)*-25 -> -3776.5549 | M1251: =IFERROR(VLOOKUP(A1251,'TLT DVD'!$A$1:$E$1249,5,FALSE),0) -> -0.19556044

Sheet HYG
A1: Date | B1: Open | C1: High | D1: Low | E1: Close | F1: SMAVG (50) on Close | G1: SMAVG (100) on Close | H1: SMAVG (200) on Close | I1: Volume | J1: SMAVG (15)
A2: 46030 | B2: 80.84 | C2: 80.93 | D2: 80.8 | E2: 80.925 | F2: 80.5797 | G2: 80.7069 | H2: 79.9975 | I2: 22342728 | J2: 27650354
A3: 46029 | B3: 80.96 | C3: 81 | D3: 80.835 | E3: 80.88 | F3: 80.5868 | G3: 80.7023 | H3: 79.9901 | I3: 27022770 | J3: 28022060
A4: 46028 | B4: 80.9 | C4: 80.94 | D4: 80.82 | E4: 80.9 | F4: 80.5908 | G4: 80.6975 | H4: 79.9818 | I4: 31721460 | J4: 28152780
A5: 46027 | B5: 80.74 | C5: 80.91 | D5: 80.7 | E5: 80.88 | F5: 80.59 | G5: 80.6946 | H5: 79.974 | I5: 38563220 | J5: 29075760
A6: 46024 | B6: 80.72 | C6: 80.72 | D6: 80.59 | E6: 80.67 | F6: 80.586 | G6: 80.6898 | H6: 79.9669 | I6: 28403304 | J6: 29474636
A7: 46022 | B7: 80.72 | C7: 80.75 | D7: 80.63 | E7: 80.63 | F7: 80.5878 | G7: 80.6853 | H7: 79.9582 | I7: 17457064 | J7: 31117898
A8: 46021 | B8: 80.64 | C8: 80.75 | D8: 80.61 | E8: 80.71 | F8: 80.5928 | G8: 80.6812 | H8: 79.9503 | I8: 20146744 | J8: 31991350
A9: 46020 | B9: 80.56 | C9: 80.66 | D9: 80.55 | E9: 80.63 | F9: 80.593 | G9: 80.6762 | H9: 79.9412 | I9: 22012766 | J9: 33525620
A10: 46017 | B10: 80.64 | C10: 80.7 | D10: 80.59 | E10: 80.6 | F10: 80.5906 | G10: 80.6728 | H10: 79.9306 | I10: 10922908 | J10: 34090556
A11: 46015 | B11: 80.51 | C11: 80.64 | D11: 80.47 | E11: 80.64 | F11: 80.5946 | G11: 80.6689 | H11: 79.9224 | I11: 10533489 | J11: 35680852
A12: 46014 | B12: 80.37 | C12: 80.49 | D12: 80.345 | E12: 80.49 | F12: 80.5926 | G12: 80.665 | H12: 79.9136 | I12: 24341796 | J12: 37313224
A13: 46013 | B13: 80.46 | C13: 80.46 | D13: 80.29 | E13: 80.43 | F13: 80.5918 | G13: 80.6599 | H13: 79.9069 | I13: 37203856 | J13: 38279944
... A1257: 44204 | B1257: 87.35 | C1257: 87.38 | D1257: 87.14 | E1257: 87.37 | F1257: 86.1788 | G1257: 85.3206 | H1257: 83.4418 | I1257: 27403774 | J1257: 24231872
A1258: 44203 | B1258: 87.18 | C1258: 87.37 | D1258: 87.13 | E1258: 87.24 | F1258: 86.1146 | G1258: 85.2927 | I1258: 25868196 | J1258: 25230734
A1259: 44202 | B1259: 87.09 | C1259: 87.34 | D1259: 86.97 | E1259: 86.99 | F1259: 86.0522 | G1259: 85.2611 | I1259: 37148244 | J1259: 25210130
A1260: 44201 | B1260: 87.02 | C1260: 87.25 | D1260: 86.98 | E1260: 87.15 | F1260: 86.0098 | G1260: 85.2335 | I1260: 33725608 | J1260: 24113948
A1261: 44200 | B1261: 87.4 | C1261: 87.4 | D1261: 86.87 | E1261: 87.12 | F1261: 85.9622 | G1261: 85.2066 | I1261: 34528344 | J1261: 23045546
A1262: 44196 | B1262: 87.21 | C1262: 87.34 | D1262: 87.17 | E1262: 87.3 | F1262: 85.9122 | G1262: 85.1798 | I1262: 12059870 | J1262: 22360426
A1263: 44195 | B1263: 87.08 | C1263: 87.28 | D1263: 87.08 | E1263: 87.23 | F1263: 85.8588 | G1263: 85.1589 | I1263: 21080160 | J1263: 23997000
A1264: 44194 | B1264: 87.31 | C1264: 87.31 | D1264: 87.0355 | E1264: 87.05 | F1264: 85.8008 | G1264: 85.1383 | I1264: 22893004 | J1264: 24018872
A1265: 44193 | B1265: 87.18 | C1265: 87.23 | D1265: 87.04 | E1265: 87.16 | F1265: 85.7524 | G1265: 85.1216 | I1265: 22575532 | J1265: 23680092
A1266: 44189 | B1266: 86.95 | C1266: 87.05 | D1266: 86.94 | E1266: 87.05 | F1266: 85.7038 | G1266: 85.1019 | I1266: 7327286 | J1266: 23465858
A1267: 44188 | B1267: 86.62 | C1267: 86.905 | D1267: 86.6 | E1267: 86.87 | F1267: 85.6586 | G1267: 85.0818 | I1267: 15913977 | J1267: 24360602
A1268: 44187 | B1268: 86.43 | C1268: 86.54 | D1268: 86.35 | E1268: 86.48 | F1268: 85.6212 | G1268: 85.0638 | I1268: 21993216 | J1268: 24880002
A1269: 44186 | B1269: 86.38 | C1269: 86.55 | D1269: 86.22 | E1269: 86.37 | F1269: 85.5992 | G1269: 85.0529 | I1269: 30308300 | J1269: 25166554
... A1357: 44060 | B1357: 84.16 | C1357: 84.62 | D1357: 84.1 | E1357: 84.58 | F1357: 83.5328 | G1357: 81.563 | I1357: 13756505 | J1357: 20110260
A1358: 44057 | B1358: 84.21 | C1358: 84.3 | D1358: 83.92 | E1358: 84.08 | F1358: 83.5304 | I1358: 14072346 | J1358: 20055274
A1359: 44056 | B1359: 84.48 | C1359: 84.81 | D1359: 84.15 | E1359: 84.23 | F1359: 83.5222 | I1359: 28444944 | J1359: 20115622
A1360: 44055 | B1360: 84.81 | C1360: 85.02 | D1360: 84.46 | E1360: 84.46 | F1360: 83.5162 | I1360: 18106368 | J1360: 20114952
A1361: 44054 | B1361: 85.25 | C1361: 85.265 | D1361: 84.4 | E1361: 84.44 | F1361: 83.4978 | I1361: 20535792 | J1361: 19924622
A1362: 44053 | B1362: 85.26 | C1362: 85.3 | D1362: 85.01 | E1362: 85.21 | F1362: 83.4634 | I1362: 13708786 | J1362: 20044370
A1363: 44050 | B1363: 85.35 | C1363: 85.35 | D1363: 85.05 | E1363: 85.17 | F1363: 83.4076 | I1363: 14290168 | J1363: 20243902
A1364: 44049 | B1364: 85.19 | C1364: 85.4 | D1364: 85.1 | E1364: 85.38 | F1364: 83.346 | I1364: 13258602 | J1364: 20815486
A1365: 44048 | B1365: 85.06 | C1365: 85.23 | D1365: 85.01 | E1365: 85.19 | F1365: 83.2786 | I1365: 14566015 | J1365: 21102942
A1366: 44047 | B1366: 84.97 | C1366: 85.065 | D1366: 84.8 | E1366: 85.04 | F1366: 83.2116 | I1366: 17120696 | J1366: 21551292
A1367: 44046 | B1367: 85.03 | C1367: 85.105 | D1367: 84.85 | E1367: 85.07 | F1367: 83.1354 | I1367: 17480820 | J1367: 22538562
A1368: 44043 | B1368: 85.2 | C1368: 85.4 | D1368: 84.9 | E1368: 85.39 | F1368: 83.0546 | I1368: 28624412 | J1368: 22709134
A1369: 44042 | B1369: 84.78 | C1369: 85.27 | D1369: 84.74 | E1369: 85.23 | F1369: 82.9678 | I1369: 54812352 | J1369: 21994398
... A1407: 43987 | B1407: 84.57 | C1407: 85.03 | D1407: 84.4 | E1407: 84.46 | F1407: 79.5932 | I1407: 35306612 | J1407: 30264322
...

Sheet Adj HYG
A1: Date | B1: Open | C1: High | D1: Low | E1: Close | F1: Volume | G1: Dividends | H1: Adj Factor DVD | I1: Adj. Open | J1: Adj. High | K1: Adj. Low | L1: Adj. Close
A2: 46030 | B2: 80.84 | C2: 80.93 | D2: 80.8 | E2: 80.925 | F2: 22342728 | G2: =IFERROR(VLOOKUP(A2,'HYG DVD'!$A$1:$B$1256,2,FALSE),0) -> 5.6441 | H2: =IFERROR(VLOOKUP(A2,'HYG DVD'!$A$1:$D$1256,4,FALSE),0) -> 0.99977605 | I2: =$H2*B2 -> 80.821896 | J2: =$H2*C2 -> 80.911876 | K2: =$H2*D2 -> 80.781905 | L2: =$H2*E2 -> 80.906877
A3: 46029 | B3: 80.96 | C3: 81 | D3: 80.835 | E3: 80.88 | F3: 27022770 | G3: =IFERROR(VLOOKUP(A3,'HYG DVD'!$A$1:$B$1256,2,FALSE),0) -> 5.6472 | H3: =IFERROR(VLOOKUP(A3,'HYG DVD'!$A$1:$D$1256,4,FALSE),0) -> 0.99977593 | I3: =$H3*B3 -> 80.941859 | J3: =$H3*C3 -> 80.98185 | K3: =$H3*D3 -> 80.816887 | L3: =$H3*E3 -> 80.861877
A4: 46028 | B4: 80.9 | C4: 80.94 | D4: 80.82 | E4: 80.9 | F4: 31721460 | G4: =IFERROR(VLOOKUP(A4,'HYG DVD'!$A$1:$B$1256,2,FALSE),0) -> 5.6458 | H4: =IFERROR(VLOOKUP(A4,'HYG DVD'!$A$1:$D$1256,4,FALSE),0) -> 0.99977599 | I4: =$H4*B4 -> 80.881877 | J4: =$H4*C4 -> 80.921868 | K4: =$H4*D4 -> 80.801895 | L4: =$H4*E4 -> 80.881877
A5: 46027 | B5: 80.74 | C5: 80.91 | D5: 80.7 | E5: 80.88 | F5: 38563220 | G5: =IFERROR(VLOOKUP(A5,'HYG DVD'!$A$1:$B$1256,2,FALSE),0) -> 5.6472 | H5: =IFERROR(VLOOKUP(A5,'HYG DVD'!$A$1:$D$1256,4,FALSE),0) -> 0.99977593 | I5: =$H5*B5 -> 80.721909 | J5: =$H5*C5 -> 80.89187 | K5: =$H5*D5 -> 80.681918 | L5: =$H5*E5 -> 80.861877
A6: 46024 | B6: 80.72 | C6: 80.72 | D6: 80.59 | E6: 80.67 | F6: 28403304 | G6: =IFERROR(VLOOKUP(A6,'HYG DVD'!$A$1:$B$1256,2,FALSE),0) -> 5.6619 | H6: =IFERROR(VLOOKUP(A6,'HYG DVD'!$A$1:$D$1256,4,FALSE),0) -> 0.99977535 | I6: =$H6*B6 -> 80.701866 | J6: =$H6*C6 -> 80.701866 | K6: =$H6*D6 -> 80.571895 | L6: =$H6*E6 -> 80.651877
A7: 46022 | B7: 80.72 | C7: 80.75 | D7: 80.63 | E7: 80.63 | F7: 17457064 | G7: =IFERROR(VLOOKUP(A7,'HYG DVD'!$A$1:$B$1256,2,FALSE),0) -> 5.6648 | H7: =IFERROR(VLOOKUP(A7,'HYG DVD'!$A$1:$D$1256,4,FALSE),0) -> 0.99977523 | I7: =$H7*B7 -> 80.701857 | J7: =$H7*C7 -> 80.73185 | K7: =$H7*D7 -> 80.611877 | L7: =$H7*E7 -> 80.611877
A8: 46021 | B8: 80.64 | C8: 80.75 | D8: 80.61 | E8: 80.71 | F8: 20146744 | G8: =IFERROR(VLOOKUP(A8,'HYG DVD'!$A$1:$B$1256,2,FALSE),0) -> 5.6591 | H8: =IFERROR(VLOOKUP(A8,'HYG DVD'!$A$1:$D$1256,4,FALSE),0) -> 0.99977546 | I8: =$H8*B8 -> 80.621893 | J8: =$H8*C8 -> 80.731868 | K8: =$H8*D8 -> 80.5919 | L8: =$H8*E8 -> 80.691877
A9: 46020 | B9: 80.56 | C9: 80.66 | D9: 80.55 | E9: 80.63 | F9: 22012766 | G9: =IFERROR(VLOOKUP(A9,'HYG DVD'!$A$1:$B$1256,2,FALSE),0) -> 5.6648 | H9: =IFERROR(VLOOKUP(A9,'HYG DVD'!$A$1:$D$1256,4,FALSE),0) -> 0.99977523 | I9: =$H9*B9 -> 80.541893 | J9: =$H9*C9 -> 80.64187 | K9: =$H9*D9 -> 80.531895 | L9: =$H9*E9 -> 80.611877
A10: 46017 | B10: 80.64 | C10: 80.7 | D10: 80.59 | E10: 80.6 | F10: 10922908 | G10: =IFERROR(VLOOKUP(A10,'HYG DVD'!$A$1:$B$1256,2,FALSE),0) -> 5.6669 | H10: =IFERROR(VLOOKUP(A10,'HYG DVD'!$A$1:$D$1256,4,FALSE),0) -> 0.99977515 | I10: =$H10*B10 -> 80.621868 | J10: =$H10*C10 -> 80.681854 | K10: =$H10*D10 -> 80.571879 | L10: =$H10*E10 -> 80.581877
A11: 46015 | B11: 80.51 | C11: 80.64 | D11: 80.47 | E11: 80.64 | F11: 10533489 | G11: =IFERROR(VLOOKUP(A11,'HYG DVD'!$A$1:$B$1256,2,FALSE),0) -> 5.664 | H11: =IFERROR(VLOOKUP(A11,'HYG DVD'!$A$1:$D$1256,4,FALSE),0) -> 0.99977526 | I11: =$H11*B11 -> 80.491906 | J11: =$H11*C11 -> 80.621877 | K11: =$H11*D11 -> 80.451915 | L11: =$H11*E11 -> 80.621877
A12: 46014 | B12: 80.37 | C12: 80.49 | D12: 80.345 | E12: 80.49 | F12: 24341796 | G12: =IFERROR(VLOOKUP(A12,'HYG DVD'!$A$1:$B$1256,2,FALSE),0) -> 5.6746 | H12: =IFERROR(VLOOKUP(A12,'HYG DVD'!$A$1:$D$1256,4,FALSE),0) -> 0.99977484 | I12: =$H12*B12 -> 80.351904 | J12: =$H12*C12 -> 80.471877 | K12: =$H12*D12 -> 80.32691 | L12: =$H12*E12 -> 80.471877
A13: 46013 | B13: 80.46 | C13: 80.46 | D13: 80.29 | E13: 80.43 | F13: 37203856 | G13: =IFERROR(VLOOKUP(A13,'HYG DVD'!$A$1:$B$1256,2,FALSE),0) -> 5.6788 | H13: =IFERROR(VLOOKUP(A13,'HYG DVD'!$A$1:$D$1256,4,FALSE),0) -> 0.99977468 | I13: =$H13*B13 -> 80.44187 | J13: =$H13*C13 -> 80.44187 | K13: =$H13*D13 -> 80.271909 | L13: =$H13*E13 -> 80.411877
... A1456: 43916 | B1456: 74.01 | C1456: 76.83 | D1456: 73.7 | E1456: 76.83 | F1456: 41965208 | G1456: =IFERROR(VLOOKUP(A1456,'HYG DVD'!$A$1:$B$1256,2,FALSE),0) -> 0 | H1456: =IFERROR(VLOOKUP(A1456,'HYG DVD'!$A$1:$D$1256,4,FALSE),0) -> 0 | I1456: =$H1456*B1456 -> 0 | J1456: =$H1456*C1456 -> 0 | K1456: =$H1456*D1456 -> 0 | L1456: =$H1456*E1456 -> 0

Sheet HYG DVD
A1: Date | B1: HYG US Equity - Dividend Indicated Yld - Gross | C1: Percentage | D1: adj factor | E1: Dividends paid
A2: 46030 | B2: 5.6441 | C2: =B2/100 -> 0.056441 | D2: =EXP(-C2*1/252) -> 0.99977605 | E2: ='Adj HYG'!E2*'HYG DVD'!C2*1/252*100 -> 1.8124952
A3: 46029 | B3: 5.6472 | C3: =B3/100 -> 0.056472 | D3: =EXP(-C3*1/252) -> 0.99977593 | E3: ='Adj HYG'!E3*'HYG DVD'!C3*1/252*100 -> 1.8124823
A4: 46028 | B4: 5.6458 | C4: =B4/100 -> 0.056458 | D4: =EXP(-C4*1/252) -> 0.99977599 | E4: ='Adj HYG'!E4*'HYG DVD'!C4*1/252*100 -> 1.812481
A5: 46027 | B5: 5.6472 | C5: =B5/100 -> 0.056472 | D5: =EXP(-C5*1/252) -> 0.99977593 | E5: ='Adj HYG'!E5*'HYG DVD'!C5*1/252*100 -> 1.8124823
A6: 46024 | B6: 5.6619 | C6: =B6/100 -> 0.056619 | D6: =EXP(-C6*1/252) -> 0.99977535 | E6: ='Adj HYG'!E6*'HYG DVD'!C6*1/252*100 -> 1.812482
A7: 46022 | B7: 5.6648 | C7: =B7/100 -> 0.056648 | D7: =EXP(-C7*1/252) -> 0.99977523 | E7: ='Adj HYG'!E7*'HYG DVD'!C7*1/252*100 -> 1.8125112
A8: 46021 | B8: 5.6591 | C8: =B8/100 -> 0.056591 | D8: =EXP(-C8*1/252) -> 0.99977546 | E8: ='Adj HYG'!E8*'HYG DVD'!C8*1/252*100 -> 1.812484
A9: 46020 | B9: 5.6648 | C9: =B9/100 -> 0.056648 | D9: =EXP(-C9*1/252) -> 0.99977523 | E9: ='Adj HYG'!E9*'HYG DVD'!C9*1/252*100 -> 1.8125112
A10: 46017 | B10: 5.6669 | C10: =B10/100 -> 0.056669 | D10: =EXP(-C10*1/252) -> 0.99977515 | E10: ='Adj HYG'!E10*'HYG DVD'!C10*1/252*100 -> 1.8125085
A11: 46015 | B11: 5.664 | C11: =B11/100 -> 0.05664 | D11: =EXP(-C11*1/252) -> 0.99977526 | E11: ='Adj HYG'!E11*'HYG DVD'!C11*1/252*100 -> 1.81248
A12: 46014 | B12: 5.6746 | C12: =B12/100 -> 0.056746 | D12: =EXP(-C12*1/252) -> 0.99977484 | E12: ='Adj HYG'!E12*'HYG DVD'!C12*1/252*100 -> 1.8124943
A13: 46013 | B13: 5.6788 | C13: =B13/100 -> 0.056788 | D13: =EXP(-C13*1/252) -> 0.99977468 | E13: ='Adj HYG'!E13*'HYG DVD'!C13*1/252*100 -> 1.8124837
... A1256: 44207 | B1256: 4.9595 | C1256: =B1256/100 -> 0.049595 | D1256: =EXP(-C1256*1/252) -> 0.99980321 | E1256: ='Adj HYG'!E1256*'HYG DVD'!C1256*1/252*100 -> 1.7102403

Sheet LQD
A1: Date | B1: Open | C1: High | D1: Low | E1: Close | F1: SMAVG (50) on Close | G1: SMAVG (100) on Close | H1: SMAVG (200) on Close | I1: Volume | J1: SMAVG (15)
A2: 46030 | B2: 110.2 | C2: 110.39 | D2: 110.19 | E2: 110.27 | F2: 110.7999 | G2: 111.0518 | H2: 109.4864 | I2: 19759688 | J2: 21670372
A3: 46029 | B3: 110.75 | C3: 110.7999 | D3: 110.525 | E3: 110.55 | F3: 110.8526 | G3: 111.0464 | H3: 109.4764 | I3: 28107442 | J3: 22465954
A4: 46028 | B4: 110.31 | C4: 110.48 | D4: 110.125 | E4: 110.47 | F4: 110.896 | G4: 111.0397 | H4: 109.4675 | I4: 31037322 | J4: 22068892
A5: 46027 | B5: 110.3 | C5: 110.51 | D5: 110.17 | E5: 110.47 | F5: 110.9372 | G5: 111.0376 | H5: 109.4597 | I5: 27771020 | J5: 22602412
A6: 46024 | B6: 110.32 | C6: 110.395 | D6: 110.035 | E6: 110.16 | F6: 110.9812 | G6: 111.0297 | H6: 109.4527 | I6: 25676222 | J6: 23546158
A7: 46022 | B7: 110.53 | C7: 110.625 | D7: 110.185 | E7: 110.19 | F7: 111.0292 | G7: 111.0239 | H7: 109.4441 | I7: 19124712 | J7: 24102376
A8: 46021 | B8: 110.57 | C8: 110.76 | D8: 110.475 | E8: 110.66 | F8: 111.0762 | G8: 111.0161 | H8: 109.434 | I8: 21486364 | J8: 24776720
A9: 46020 | B9: 110.69 | C9: 110.79 | D9: 110.59 | E9: 110.79 | F9: 111.107 | G9: 111.0071 | H9: 109.4204 | I9: 18943860 | J9: 25265312
A10: 46017 | B10: 110.75 | C10: 110.8 | D10: 110.47 | E10: 110.64 | F10: 111.1396 | G10: 110.9979 | H10: 109.4064 | I10: 10589292 | J10: 25700390
A11: 46015 | B11: 110.43 | C11: 110.65 | D11: 110.34 | E11: 110.65 | F11: 111.1688 | G11: 110.9905 | H11: 109.3915 | I11: 6400631 | J11: 26984206
A12: 46014 | B12: 109.91 | C12: 110.27 | D12: 109.85 | E12: 110.22 | F12: 111.1978 | G12: 110.9822 | H12: 109.3782 | I12: 16137321 | J12: 27957366
A13: 46013 | B13: 110.18 | C13: 110.205 | D13: 110.01 | E13: 110.11 | F13: 111.228 | G13: 110.9763 | H13: 109.3706 | I13: 17335284 | J13: 29211882
... A1257: 44204 | B1257: 135.78 | C1257: 135.89 | D1257: 135.45 | E1257: 135.76 | F1257: 136.6936 | G1257: 135.9872 | H1257: 134.0437 | I1257: 13341444 | J1257: 10327275
A1258: 44203 | B1258: 135.56 | C1258: 135.945 | D1258: 135.54 | E1258: 135.86 | F1258: 136.6874 | G1258: 135.9865 | I1258: 11886103 | J1258: 10259581
A1259: 44202 | B1259: 135.78 | C1259: 135.9789 | D1259: 135.4 | E1259: 135.88 | F1259: 136.6682 | G1259: 135.982 | I1259: 19136594 | J1259: 10284144
A1260: 44201 | B1260: 137.06 | C1260: 137.06 | D1260: 136.55 | E1260: 136.99 | F1260: 136.643 | G1260: 135.9833 | I1260: 16294445 | J1260: 9541973
A1261: 44200 | B1261: 137.89 | C1261: 137.89 | D1261: 137.375 | E1261: 137.43 | F1261: 136.5888 | G1261: 135.9859 | I1261: 14891417 | J1261: 9057210
A1262: 44196 | B1262: 138.04 | C1262: 138.215 | D1262: 137.96 | E1262: 138.13 | F1262: 136.5318 | G1262: 135.9875 | I1262: 6932337 | J1262: 8966286
A1263: 44195 | B1263: 137.89 | C1263: 138.11 | D1263: 137.79 | E1263: 138.1 | F1263: 136.4652 | G1263: 135.9908 | I1263: 5343075 | J1263: 9892443
A1264: 44194 | B1264: 137.61 | C1264: 137.93 | D1264: 137.6 | E1264: 137.92 | F1264: 136.4048 | G1264: 135.9974 | I1264: 6581765 | J1264: 10389416
A1265: 44193 | B1265: 137.57 | C1265: 137.9 | D1265: 137.5 | E1265: 137.86 | F1265: 136.3532 | G1265: 136.0097 | I1265: 6279173 | J1265: 11063795
A1266: 44189 | B1266: 137.48 | C1266: 137.83 | D1266: 137.48 | E1266: 137.77 | F1266: 136.3074 | G1266: 136.0167 | I1266: 3397020 | J1266: 11479931
A1267: 44188 | B1267: 136.92 | C1267: 137.315 | D1267: 136.65 | E1267: 137.3 | F1267: 136.2662 | G1267: 136.0265 | I1267: 7553144 | J1267: 12512708
A1268: 44187 | B1268: 137.19 | C1268: 137.29 | D1268: 136.9871 | E1268: 137.27 | F1268: 136.2318 | G1268: 136.0359 | I1268: 10226790 | J1268: 13051681
A1269: 44186 | B1269: 137.13 | C1269: 137.1416 | D1269: 136.665 | E1269: 136.89 | F1269: 136.2006 | G1269: 136.0467 | I1269: 11925031 | J1269: 13632144
... A1357: 44060 | B1357: 135.75 | C1357: 135.92 | D1357: 135.5721 | E1357: 135.69 | F1357: 135.8672 | G1357: 132.1003 | I1357: 9523060 | J1357: 10864484
A1358: 44057 | B1358: 135.85 | C1358: 136.12 | D1358: 135.28 | E1358: 135.41 | F1358: 135.7986 | I1358: 12409377 | J1358: 10652788
A1359: 44056 | B1359: 137.15 | C1359: 137.23 | D1359: 135.75 | E1359: 136.01 | F1359: 135.722 | I1359: 20754788 | J1359: 10432599
A1360: 44055 | B1360: 137.5 | C1360: 137.7284 | D1360: 137.1 | E1360: 137.25 | F1360: 135.6414 | I1360: 11902608 | J1360: 9685231
A1361: 44054 | B1361: 138 | C1361: 138.09 | D1361: 137.485 | E1361: 137.59 | F1361: 135.5376 | I1361: 12870521 | J1361: 9307049
A1362: 44053 | B1362: 138.98 | C1362: 138.99 | D1362: 138.41 | E1362: 138.46 | F1362: 135.4186 | I1362: 6137147 | J1362: 8963182
A1363: 44050 | B1363: 139.29 | C1363: 139.38 | D1363: 138.72 | E1363: 138.76 | F1363: 135.2898 | I1363: 7405328 | J1363: 9036994
A1364: 44049 | B1364: 138.99 | C1364: 139.2585 | D1364: 138.93 | E1364: 139.15 | F1364: 135.138 | I1364: 8067832 | J1364: 8948545
A1365: 44048 | B1365: 138.54 | C1365: 138.8 | D1365: 138.43 | E1365: 138.56 | F1365: 134.9762 | I1365: 11601952 | J1365: 8928145
A1366: 44047 | B1366: 138.49 | C1366: 138.75 | D1366: 138.41 | E1366: 138.75 | F1366: 134.8154 | I1366: 10101937 | J1366: 8742393
A1367: 44046 | B1367: 137.95 | C1367: 138.34 | D1367: 137.8099 | E1367: 138.24 | F1367: 134.6544 | I1367: 10916285 | J1367: 8902634
A1368: 44043 | B1368: 138.14 | C1368: 138.46 | D1368: 137.93 | E1368: 138.35 | F1368: 134.5036 | I1368: 11788727 | J1368: 9672031
A1369: 44042 | B1369: 138.23 | C1369: 138.31 | D1369: 137.96 | E1369: 138.16 | F1369: 134.3526 | I1369: 8939909 | J1369: 9488988
... A1407: 43987 | B1407: 132.09 | C1407: 132.45 | D1407: 131.5 | E1407: 132.26 | F1407: 128.3334 | I1407: 22147360 | J1407: 13942479
...

Sheet Adj LQD
A1: Date | B1: Open | C1: High | D1: Low | E1: Close | F1: Volume | G1: Dividends | H1: Adj Factor DVD | I1: Adj. Open | J1: Adj. High | K1: Adj. Low | L1: Adj. Close
A2: 46030 | B2: 110.2 | C2: 110.39 | D2: 110.19 | E2: 110.27 | F2: 19759688 | G2: =IFERROR(VLOOKUP(A2,'LQD DVD'!$A$1:$D$1256,2,FALSE),0) -> 4.7495 | H2: =IFERROR(VLOOKUP(A2,'LQD DVD'!$A$1:$D$1256,4,FALSE),0) -> 0.99981155 | I2: =B2*$H2 -> 110.17923 | J2: =C2*$H2 -> 110.3692 | K2: =D2*$H2 -> 110.16923 | L2: =E2*$H2 -> 110.24922
A3: 46029 | B3: 110.75 | C3: 110.7999 | D3: 110.525 | E3: 110.55 | F3: 28107442 | G3: =IFERROR(VLOOKUP(A3,'LQD DVD'!$A$1:$D$1256,2,FALSE),0) -> 4.7377 | H3: =IFERROR(VLOOKUP(A3,'LQD DVD'!$A$1:$D$1256,4,FALSE),0) -> 0.99981201 | I3: =B3*$H3 -> 110.72918 | J3: =C3*$H3 -> 110.77907 | K3: =D3*$H3 -> 110.50422 | L3: =E3*$H3 -> 110.52922
A4: 46028 | B4: 110.31 | C4: 110.48 | D4: 110.125 | E4: 110.47 | F4: 31037322 | G4: =IFERROR(VLOOKUP(A4,'LQD DVD'!$A$1:$D$1256,2,FALSE),0) -> 4.7411 | H4: =IFERROR(VLOOKUP(A4,'LQD DVD'!$A$1:$D$1256,4,FALSE),0) -> 0.99981188 | I4: =B4*$H4 -> 110.28925 | J4: =C4*$H4 -> 110.45922 | K4: =D4*$H4 -> 110.10428 | L4: =E4*$H4 -> 110.44922
A5: 46027 | B5: 110.3 | C5: 110.51 | D5: 110.17 | E5: 110.47 | F5: 27771020 | G5: =IFERROR(VLOOKUP(A5,'LQD DVD'!$A$1:$D$1256,2,FALSE),0) -> 4.7411 | H5: =IFERROR(VLOOKUP(A5,'LQD DVD'!$A$1:$D$1256,4,FALSE),0) -> 0.99981188 | I5: =B5*$H5 -> 110.27925 | J5: =C5*$H5 -> 110.48921 | K5: =D5*$H5 -> 110.14927 | L5: =E5*$H5 -> 110.44922
A6: 46024 | B6: 110.32 | C6: 110.395 | D6: 110.035 | E6: 110.16 | F6: 25676222 | G6: =IFERROR(VLOOKUP(A6,'LQD DVD'!$A$1:$D$1256,2,FALSE),0) -> 4.7544 | H6: =IFERROR(VLOOKUP(A6,'LQD DVD'!$A$1:$D$1256,4,FALSE),0) -> 0.99981135 | I6: =B6*$H6 -> 110.29919 | J6: =C6*$H6 -> 110.37417 | K6: =D6*$H6 -> 110.01424 | L6: =E6*$H6 -> 110.13922
A7: 46022 | B7: 110.53 | C7: 110.625 | D7: 110.185 | E7: 110.19 | F7: 19124712 | G7: =IFERROR(VLOOKUP(A7,'LQD DVD'!$A$1:$D$1256,2,FALSE),0) -> 4.7531 | H7: =IFERROR(VLOOKUP(A7,'LQD DVD'!$A$1:$D$1256,4,FALSE),0) -> 0.9998114 | I7: =B7*$H7 -> 110.50915 | J7: =C7*$H7 -> 110.60414 | K7: =D7*$H7 -> 110.16422 | L7: =E7*$H7 -> 110.16922
A8: 46021 | B8: 110.57 | C8: 110.76 | D8: 110.475 | E8: 110.66 | F8: 21486364 | G8: =IFERROR(VLOOKUP(A8,'LQD DVD'!$A$1:$D$1256,2,FALSE),0) -> 4.733 | H8: =IFERROR(VLOOKUP(A8,'LQD DVD'!$A$1:$D$1256,4,FALSE),0) -> 0.9998122 | I8: =B8*$H8 -> 110.54923 | J8: =C8*$H8 -> 110.7392 | K8: =D8*$H8 -> 110.45425 | L8: =E8*$H8 -> 110.63922
A9: 46020 | B9: 110.69 | C9: 110.79 | D9: 110.59 | E9: 110.79 | F9: 18943860 | G9: =IFERROR(VLOOKUP(A9,'LQD DVD'!$A$1:$D$1256,2,FALSE),0) -> 4.7274 | H9: =IFERROR(VLOOKUP(A9,'LQD DVD'!$A$1:$D$1256,4,FALSE),0) -> 0.99981242 | I9: =B9*$H9 -> 110.66924 | J9: =C9*$H9 -> 110.76922 | K9: =D9*$H9 -> 110.56926 | L9: =E9*$H9 -> 110.76922
A10: 46017 | B10: 110.75 | C10: 110.8 | D10: 110.47 | E10: 110.64 | F10: 10589292 | G10: =IFERROR(VLOOKUP(A10,'LQD DVD'!$A$1:$D$1256,2,FALSE),0) -> 4.7338 | H10: =IFERROR(VLOOKUP(A10,'LQD DVD'!$A$1:$D$1256,4,FALSE),0) -> 0.99981217 | I10: =B10*$H10 -> 110.7292 | J10: =C10*$H10 -> 110.77919 | K10: =D10*$H10 -> 110.44925 | L10: =E10*$H10 -> 110.61922
A11: 46015 | B11: 110.43 | C11: 110.65 | D11: 110.34 | E11: 110.65 | F11: 6400631 | G11: =IFERROR(VLOOKUP(A11,'LQD DVD'!$A$1:$D$1256,2,FALSE),0) -> 4.7334 | H11: =IFERROR(VLOOKUP(A11,'LQD DVD'!$A$1:$D$1256,4,FALSE),0) -> 0.99981218 | I11: =B11*$H11 -> 110.40926 | J11: =C11*$H11 -> 110.62922 | K11: =D11*$H11 -> 110.31928 | L11: =E11*$H11 -> 110.62922
A12: 46014 | B12: 109.91 | C12: 110.27 | D12: 109.85 | E12: 110.22 | F12: 16137321 | G12: =IFERROR(VLOOKUP(A12,'LQD DVD'!$A$1:$D$1256,2,FALSE),0) -> 4.7519 | H12: =IFERROR(VLOOKUP(A12,'LQD DVD'!$A$1:$D$1256,4,FALSE),0) -> 0.99981145 | I12: =B12*$H12 -> 109.88928 | J12: =C12*$H12 -> 110.24921 | K12: =D12*$H12 -> 109.82929 | L12: =E12*$H12 -> 110.19922
A13: 46013 | B13: 110.18 | C13: 110.205 | D13: 110.01 | E13: 110.11 | F13: 17335284 | G13: =IFERROR(VLOOKUP(A13,'LQD DVD'!$A$1:$D$1256,2,FALSE),0) -> 4.7566 | H13: =IFERROR(VLOOKUP(A13,'LQD DVD'!$A$1:$D$1256,4,FALSE),0) -> 0.99981126 | I13: =B13*$H13 -> 110.15921 | J13: =C13*$H13 -> 110.1842 | K13: =D13*$H13 -> 109.98924 | L13: =E13*$H13 -> 110.08922
... A1456: 43916 | B1456: 122.5 | C1456: 123.33 | D1456: 121.25 | E1456: 122.68 | F1456: 21893500 | G1456: =IFERROR(VLOOKUP(A1456,'LQD DVD'!$A$1:$D$1256,2,FALSE),0) -> 0 | H1456: =IFERROR(VLOOKUP(A1456,'LQD DVD'!$A$1:$D$1256,4,FALSE),0) -> 0 | I1456: =B1456*$H1456 -> 0 | J1456: =C1456*$H1456 -> 0 | K1456: =D1456*$H1456 -> 0 | L1456: =E1456*$H1456 -> 0

Sheet LQD DVD
A1: Date | B1: LQD US Equity - Dividend Indicated Yld - Gross | C1: Percentage | D1: adj factor | E1: Dividends paid
A2: 46030 | B2: 4.7495 | C2: =B2/100 -> 0.047495 | D2: =EXP(-C2*1/252) -> 0.99981155 | E2: ='Adj LQD'!E2*'LQD DVD'!C2*1/252*200 -> 4.1565664
A3: 46029 | B3: 4.7377 | C3: =B3/100 -> 0.047377 | D3: =EXP(-C3*1/252) -> 0.99981201 | E3: ='Adj LQD'!E3*'LQD DVD'!C3*1/252*200 -> 4.1567677
A4: 46028 | B4: 4.7411 | C4: =B4/100 -> 0.047411 | D4: =EXP(-C4*1/252) -> 0.99981188 | E4: ='Adj LQD'!E4*'LQD DVD'!C4*1/252*200 -> 4.1567406
A5: 46027 | B5: 4.7411 | C5: =B5/100 -> 0.047411 | D5: =EXP(-C5*1/252) -> 0.99981188 | E5: ='Adj LQD'!E5*'LQD DVD'!C5*1/252*200 -> 4.1567406
A6: 46024 | B6: 4.7544 | C6: =B6/100 -> 0.047544 | D6: =EXP(-C6*1/252) -> 0.99981135 | E6: ='Adj LQD'!E6*'LQD DVD'!C6*1/252*200 -> 4.156704
A7: 46022 | B7: 4.7531 | C7: =B7/100 -> 0.047531 | D7: =EXP(-C7*1/252) -> 0.9998114 | E7: ='Adj LQD'!E7*'LQD DVD'!C7*1/252*200 -> 4.1566991
A8: 46021 | B8: 4.733 | C8: =B8/100 -> 0.04733 | D8: =EXP(-C8*1/252) -> 0.9998122 | E8: ='Adj LQD'!E8*'LQD DVD'!C8*1/252*200 -> 4.156776
A9: 46020 | B9: 4.7274 | C9: =B9/100 -> 0.047274 | D9: =EXP(-C9*1/252) -> 0.99981242 | E9: ='Adj LQD'!E9*'LQD DVD'!C9*1/252*200 -> 4.1567353
A10: 46017 | B10: 4.7338 | C10: =B10/100 -> 0.047338 | D10: =EXP(-C10*1/252) -> 0.99981217 | E10: ='Adj LQD'!E10*'LQD DVD'!C10*1/252*200 -> 4.1567272
A11: 46015 | B11: 4.7334 | C11: =B11/100 -> 0.047334 | D11: =EXP(-C11*1/252) -> 0.99981218 | E11: ='Adj LQD'!E11*'LQD DVD'!C11*1/252*200 -> 4.1567517
A12: 46014 | B12: 4.7519 | C12: =B12/100 -> 0.047519 | D12: =EXP(-C12*1/252) -> 0.99981145 | E12: ='Adj LQD'!E12*'LQD DVD'!C12*1/252*200 -> 4.1567811
A13: 46013 | B13: 4.7566 | C13: =B13/100 -> 0.047566 | D13: =EXP(-C13*1/252) -> 0.99981126 | E13: ='Adj LQD'!E13*'LQD DVD'!C13*1/252*200 -> 4.1567399
... A1256: 44207 | B1256: 2.4856 | C1256: =B1256/100 -> 0.024856 | D1256: =EXP(-C1256*1/252) -> 0.99990137 | E1256: ='Adj LQD'!E1256*'LQD DVD'!C1256*1/252*200 -> 2.6666937

Sheet SPY
A1: Date | B1: Open | C1: High | D1: Low | E1: Close | F1: SMAVG (50) on Close | G1: SMAVG (100) on Close | H1: SMAVG (200) on Close | I1: Volume | J1: SMAVG (15)
A2: 46030 | B2: 688.82 | C2: 690.615 | D2: 687.49 | E2: 689.28 | F2: 679.8634 | G2: 669.222 | H2: 629.9585 | I2: 53325408 | J2: 72112680
A3: 46029 | B3: 692.19 | C3: 693.96 | D3: 689.32 | E3: 689.58 | F3: 679.7822 | G3: 668.7634 | H3: 629.3824 | I3: 75588336 | J3: 76692840
A4: 46028 | B4: 687.93 | C4: 692.315 | D4: 687.78 | E4: 691.81 | F4: 679.5356 | G4: 668.3171 | H4: 628.7544 | I4: 69273824 | J4: 77707680
A5: 46027 | B5: 686.54 | C5: 689.43 | D5: 686.375 | E5: 687.72 | F5: 679.1346 | G5: 667.8479 | H5: 628.1228 | I5: 71927192 | J5: 80633448
A6: 46024 | B6: 685.71 | C6: 686.87 | D6: 679.82 | E6: 683.17 | F6: 678.7362 | G6: 667.3976 | H6: 627.5198 | I6: 89377200 | J6: 81583216
A7: 46022 | B7: 687.14 | C7: 687.36 | D7: 681.71 | E7: 681.92 | F7: 678.4986 | G7: 666.9251 | H7: 626.9091 | I7: 74144800 | J7: 81336160
A8: 46021 | B8: 687.445 | C8: 688.555 | D8: 686.58 | E8: 687.01 | F8: 678.2862 | G8: 666.4777 | H8: 626.3353 | I8: 47160672 | J8: 80280512
A9: 46020 | B9: 687.54 | C9: 689.2 | D9: 686.07 | E9: 687.85 | F9: 677.8338 | G9: 665.9301 | H9: 625.7142 | I9: 62559504 | J9: 80818560
A10: 46017 | B10: 690.64 | C10: 691.66 | D10: 689.27 | E10: 690.31 | F10: 677.2896 | G10: 665.3794 | H10: 625.0321 | I10: 41613348 | J10: 81930664
A11: 46015 | B11: 687.95 | C11: 690.83 | D11: 687.8 | E11: 690.38 | F11: 676.7868 | G11: 664.756 | H11: 624.3749 | I11: 39445560 | J11: 83287800
A12: 46014 | B12: 683.92 | C12: 688.2 | D12: 683.87 | E12: 687.96 | F12: 676.2238 | G12: 664.1639 | H12: 623.7026 | I12: 64839952 | J12: 84473992
A13: 46013 | B13: 683.94 | C13: 685.36 | D13: 680.5868 | E13: 684.83 | F13: 675.7254 | G13: 663.5015 | H13: 623.0657 | I13: 69556736 | J13: 84348256
... A1257: 44204 | B1257: 380.59 | C1257: 381.49 | D1257: 377.1 | E1257: 381.26 | F1257: 361.2222 | G1257: 350.7267 | H1257: 326.3192 | I1257: 71677208 | J1257: 70922120
A1258: 44203 | B1258: 376.1 | C1258: 379.9 | D1258: 375.91 | E1258: 379.1 | F1258: 360.3614 | G1258: 350.2932 | I1258: 68766816 | J1258: 70038344
A1259: 44202 | B1259: 369.71 | C1259: 376.98 | D1259: 369.12 | E1259: 373.55 | F1259: 359.5672 | G1259: 349.8706 | I1259: 107997672 | J1259: 69725296
A1260: 44201 | B1260: 368.1 | C1260: 372.5 | D1260: 368.05 | E1260: 371.33 | F1260: 359.0118 | G1260: 349.5034 | I1260: 66426228 | J1260: 67139864
A1261: 44200 | B1261: 375.31 | C1261: 375.45 | D1261: 364.82 | E1261: 368.79 | F1261: 358.4774 | G1261: 349.1645 | I1261: 110210808 | J1261: 66558020
A1262: 44196 | B1262: 371.78 | C1262: 374.66 | D1262: 371.232 | E1262: 373.88 | F1262: 357.9562 | G1262: 348.8046 | I1262: 78520704 | J1262: 63059656
A1263: 44195 | B1263: 372.34 | C1263: 373.1 | D1263: 371.57 | E1263: 371.99 | F1263: 357.3462 | G1263: 348.4215 | I1263: 49455260 | J1263: 62764832
A1264: 44194 | B1264: 373.81 | C1264: 374 | D1264: 370.83 | E1264: 371.46 | F1264: 356.7466 | G1264: 348.0473 | I1264: 53680452 | J1264: 62298404
A1265: 44193 | B1265: 371.74 | C1265: 372.59 | D1265: 371.07 | E1265: 372.17 | F1265: 356.2632 | G1265: 347.676 | I1265: 39000400 | J1265: 61982656
A1266: 44189 | B1266: 368.08 | C1266: 369.03 | D1266: 367.45 | E1266: 369 | F1266: 355.7698 | G1266: 347.2754 | I1266: 26457852 | J1266: 62765956
A1267: 44188 | B1267: 368.28 | C1267: 369.62 | D1267: 367.2172 | E1267: 367.57 | F1267: 355.3484 | G1267: 346.886 | I1267: 46201400 | J1267: 65194232
A1268: 44187 | B1268: 368.21 | C1268: 368.3317 | D1268: 366.03 | E1268: 367.24 | F1268: 354.9996 | G1268: 346.4982 | I1268: 48388464 | J1268: 65175940
A1269: 44186 | B1269: 364.97 | C1269: 378.46 | D1269: 362.03 | E1269: 367.86 | F1269: 354.7034 | G1269: 346.091 | I1269: 96386744 | J1269: 66917040
... A1357: 44060 | B1357: 337.94 | C1357: 338.34 | D1357: 336.8517 | E1357: 337.91 | F1357: 319.68 | G1357: 301.9118 | I1357: 35480976 | J1357: 52275888
A1358: 44057 | B1358: 336.41 | C1358: 337.42 | D1358: 335.62 | E1358: 336.84 | F1358: 319.3086 | I1358: 47260392 | J1358: 53130020
A1359: 44056 | B1359: 336.61 | C1359: 338.2514 | D1359: 335.83 | E1359: 336.83 | F1359: 318.799 | I1359: 41816144 | J1359: 54897104
A1360: 44055 | B1360: 335.44 | C1360: 338.28 | D1360: 332.8377 | E1360: 337.44 | F1360: 318.306 | I1360: 53826128 | J1360: 57158560
A1361: 44054 | B1361: 336.85 | C1361: 337.54 | D1361: 332.01 | E1361: 332.8 | F1361: 317.7188 | I1361: 69601088 | J1361: 57423012
A1362: 44053 | B1362: 335.06 | C1362: 335.77 | D1362: 332.955 | E1362: 335.57 | F1362: 317.1738 | I1362: 44282088 | J1362: 56616204
A1363: 44050 | B1363: 333.28 | C1363: 334.88 | D1363: 332.3 | E1363: 334.57 | F1363: 316.5488 | I1363: 57308272 | J1363: 57417988
A1364: 44049 | B1364: 331.4799 | C1364: 334.46 | D1364: 331.13 | E1364: 334.33 | F1364: 315.9168 | I1364: 43679448 | J1364: 57782428
A1365: 44048 | B1365: 331.47 | C1365: 332.39 | D1365: 331.18 | E1365: 332.11 | F1365: 315.3008 | I1365: 42866352 | J1365: 58511968
A1366: 44047 | B1366: 327.86 | C1366: 330.06 | D1366: 327.86 | E1366: 330.06 | F1366: 314.6402 | I1366: 41917892 | J1366: 61467312
A1367: 44046 | B1367: 328.32 | C1367: 329.62 | D1367: 327.73 | E1367: 328.79 | F1367: 313.9478 | I1367: 53077948 | J1367: 64916584
A1368: 44043 | B1368: 325.9 | C1368: 326.63 | D1368: 321.33 | E1368: 326.52 | F1368: 313.2696 | I1368: 85210752 | J1368: 68244552
A1369: 44042 | B1369: 321.9 | C1369: 324.41 | D1369: 319.64 | E1369: 323.96 | F1369: 312.6778 | I1369: 61861712 | J1369: 66400528
... A1407: 43987 | B1407: 317.23 | C1407: 321.275 | D1407: 317.16 | E1407: 319.34 | F1407: 284.1436 | I1407: 150524672 | J1407: 93900376
...

Sheet Adj SPY
A1: Date | B1: Open | C1: High | D1: Low | E1: Close | F1: Volume | G1: Dividends | H1: Adj Factor DVD | I1: Adj. Open | J1: Adj. High | K1: Adj. Low | L1: Adj. Close
A2: 46030 | B2: 688.82 | C2: 690.615 | D2: 687.49 | E2: 689.28 | F2: 53325408 | G2: =IFERROR(VLOOKUP(A2,'SPY DVD'!$A$1:$D$1256,2,FALSE),0) -> 1.1564 | H2: =IFERROR(VLOOKUP(A2,'SPY DVD'!$A$1:$D$1256,4,FALSE),0) -> 0.99995411 | I2: =B2*$H2 -> 688.78839 | J2: =C2*$H2 -> 690.58331 | K2: =D2*$H2 -> 687.45845 | L2: =E2*$H2 -> 689.24837
A3: 46029 | B3: 692.19 | C3: 693.96 | D3: 689.32 | E3: 689.58 | F3: 75588336 | G3: =IFERROR(VLOOKUP(A3,'SPY DVD'!$A$1:$D$1256,2,FALSE),0) -> 1.1563 | H3: =IFERROR(VLOOKUP(A3,'SPY DVD'!$A$1:$D$1256,4,FALSE),0) -> 0.99995412 | I3: =B3*$H3 -> 692.15824 | J3: =C3*$H3 -> 693.92816 | K3: =D3*$H3 -> 689.28837 | L3: =E3*$H3 -> 689.54836
A4: 46028 | B4: 687.93 | C4: 692.315 | D4: 687.78 | E4: 691.81 | F4: 69273824 | G4: =IFERROR(VLOOKUP(A4,'SPY DVD'!$A$1:$D$1256,2,FALSE),0) -> 1.1526 | H4: =IFERROR(VLOOKUP(A4,'SPY DVD'!$A$1:$D$1256,4,FALSE),0) -> 0.99995426 | I4: =B4*$H4 -> 687.89854 | J4: =C4*$H4 -> 692.28334 | K4: =D4*$H4 -> 687.74854 | L4: =E4*$H4 -> 691.77836
A5: 46027 | B5: 686.54 | C5: 689.43 | D5: 686.375 | E5: 687.72 | F5: 71927192 | G5: =IFERROR(VLOOKUP(A5,'SPY DVD'!$A$1:$D$1256,2,FALSE),0) -> 1.1594 | H5: =IFERROR(VLOOKUP(A5,'SPY DVD'!$A$1:$D$1256,4,FALSE),0) -> 0.99995399 | I5: =B5*$H5 -> 686.50841 | J5: =C5*$H5 -> 689.39828 | K5: =D5*$H5 -> 686.34342 | L5: =E5*$H5 -> 687.68836
A6: 46024 | B6: 685.71 | C6: 686.87 | D6: 679.82 | E6: 683.17 | F6: 89377200 | G6: =IFERROR(VLOOKUP(A6,'SPY DVD'!$A$1:$D$1256,2,FALSE),0) -> 1.1671 | H6: =IFERROR(VLOOKUP(A6,'SPY DVD'!$A$1:$D$1256,4,FALSE),0) -> 0.99995369 | I6: =B6*$H6 -> 685.67824 | J6: =C6*$H6 -> 686.83819 | K6: =D6*$H6 -> 679.78852 | L6: =E6*$H6 -> 683.13836
A7: 46022 | B7: 687.14 | C7: 687.36 | D7: 681.71 | E7: 681.92 | F7: 74144800 | G7: =IFERROR(VLOOKUP(A7,'SPY DVD'!$A$1:$D$1256,2,FALSE),0) -> 1.1693 | H7: =IFERROR(VLOOKUP(A7,'SPY DVD'!$A$1:$D$1256,4,FALSE),0) -> 0.9999536 | I7: =B7*$H7 -> 687.10812 | J7: =C7*$H7 -> 687.32811 | K7: =D7*$H7 -> 681.67837 | L7: =E7*$H7 -> 681.88836
A8: 46021 | B8: 687.445 | C8: 688.555 | D8: 686.58 | E8: 687.01 | F8: 47160672 | G8: =IFERROR(VLOOKUP(A8,'SPY DVD'!$A$1:$D$1256,2,FALSE),0) -> 1.1606 | H8: =IFERROR(VLOOKUP(A8,'SPY DVD'!$A$1:$D$1256,4,FALSE),0) -> 0.99995395 | I8: =B8*$H8 -> 687.41334 | J8: =C8*$H8 -> 688.52329 | K8: =D8*$H8 -> 686.54838 | L8: =E8*$H8 -> 686.97836
A9: 46020 | B9: 687.54 | C9: 689.2 | D9: 686.07 | E9: 687.85 | F9: 62559504 | G9: =IFERROR(VLOOKUP(A9,'SPY DVD'!$A$1:$D$1256,2,FALSE),0) -> 1.1592 | H9: =IFERROR(VLOOKUP(A9,'SPY DVD'!$A$1:$D$1256,4,FALSE),0) -> 0.999954 | I9: =B9*$H9 -> 687.50837 | J9: =C9*$H9 -> 689.1683 | K9: =D9*$H9 -> 686.03844 | L9: =E9*$H9 -> 687.81836
A10: 46017 | B10: 690.64 | C10: 691.66 | D10: 689.27 | E10: 690.31 | F10: 41613348 | G10: =IFERROR(VLOOKUP(A10,'SPY DVD'!$A$1:$D$1256,2,FALSE),0) -> 1.1551 | H10: =IFERROR(VLOOKUP(A10,'SPY DVD'!$A$1:$D$1256,4,FALSE),0) -> 0.99995416 | I10: =B10*$H10 -> 690.60834 | J10: =C10*$H10 -> 691.6283 | K10: =D10*$H10 -> 689.23841 | L10: =E10*$H10 -> 690.27836
A11: 46015 | B11: 687.95 | C11: 690.83 | D11: 687.8 | E11: 690.38 | F11: 39445560 | G11: =IFERROR(VLOOKUP(A11,'SPY DVD'!$A$1:$D$1256,2,FALSE),0) -> 1.1549 | H11: =IFERROR(VLOOKUP(A11,'SPY DVD'!$A$1:$D$1256,4,FALSE),0) -> 0.99995417 | I11: =B11*$H11 -> 687.91847 | J11: =C11*$H11 -> 690.79834 | K11: =D11*$H11 -> 687.76848 | L11: =E11*$H11 -> 690.34836
A12: 46014 | B12: 683.92 | C12: 688.2 | D12: 683.87 | E12: 687.96 | F12: 64839952 | G12: =IFERROR(VLOOKUP(A12,'SPY DVD'!$A$1:$D$1256,2,FALSE),0) -> 1.159 | H12: =IFERROR(VLOOKUP(A12,'SPY DVD'!$A$1:$D$1256,4,FALSE),0) -> 0.99995401 | I12: =B12*$H12 -> 683.88855 | J12: =C12*$H12 -> 688.16835 | K12: =D12*$H12 -> 683.83855 | L12: =E12*$H12 -> 687.92836
A13: 46013 | B13: 683.94 | C13: 685.36 | D13: 680.5868 | E13: 684.83 | F13: 69556736 | G13: =IFERROR(VLOOKUP(A13,'SPY DVD'!$A$1:$D$1256,2,FALSE),0) -> 1.1643 | H13: =IFERROR(VLOOKUP(A13,'SPY DVD'!$A$1:$D$1256,4,FALSE),0) -> 0.9999538 | I13: =B13*$H13 -> 683.9084 | J13: =C13*$H13 -> 685.32834 | K13: =D13*$H13 -> 680.55536 | L13: =E13*$H13 -> 684.79836
... A1456: 43916 | B1456: 249.52 | C1456: 262.8 | D1456: 249.05 | E1456: 261.2 | F1456: 257632816 | G1456: =IFERROR(VLOOKUP(A1456,'SPY DVD'!$A$1:$D$1256,2,FALSE),0) -> 0 | H1456: =IFERROR(VLOOKUP(A1456,'SPY DVD'!$A$1:$D$1256,4,FALSE),0) -> 0 | I1456: =B1456*$H1456 -> 0 | J1456: =C1456*$H1456 -> 0 | K1456: =D1456*$H1456 -> 0 | L1456: =E1456*$H1456 -> 0

Sheet SPY DVD
A1: Date | B1: SPY US Equity - Dividend Indicated Yld - Gross | C1: Percentage | D1: adj factor | E1: Dividends paid
A2: 46030 | B2: 1.1564 | C2: =B2/100 -> 0.011564 | D2: =EXP(-C2*1/252) -> 0.99995411 | E2: ='Adj SPY'!E2*'SPY DVD'!C2*1/252*-10 -> -0.31630293
A3: 46029 | B3: 1.1563 | C3: =B3/100 -> 0.011563 | D3: =EXP(-C3*1/252) -> 0.99995412 | E3: ='Adj SPY'!E3*'SPY DVD'!C3*1/252*-10 -> -0.31641324
A4: 46028 | B4: 1.1526 | C4: =B4/100 -> 0.011526 | D4: =EXP(-C4*1/252) -> 0.99995426 | E4: ='Adj SPY'!E4*'SPY DVD'!C4*1/252*-10 -> -0.31642072
A5: 46027 | B5: 1.1594 | C5: =B5/100 -> 0.011594 | D5: =EXP(-C5*1/252) -> 0.99995399 | E5: ='Adj SPY'!E5*'SPY DVD'!C5*1/252*-10 -> -0.31640578
A6: 46024 | B6: 1.1671 | C6: =B6/100 -> 0.011671 | D6: =EXP(-C6*1/252) -> 0.99995369 | E6: ='Adj SPY'!E6*'SPY DVD'!C6*1/252*-10 -> -0.31639988
A7: 46022 | B7: 1.1693 | C7: =B7/100 -> 0.011693 | D7: =EXP(-C7*1/252) -> 0.9999536 | E7: ='Adj SPY'!E7*'SPY DVD'!C7*1/252*-10 -> -0.31641629
A8: 46021 | B8: 1.1606 | C8: =B8/100 -> 0.011606 | D8: =EXP(-C8*1/252) -> 0.99995395 | E8: ='Adj SPY'!E8*'SPY DVD'!C8*1/252*-10 -> -0.31640627
A9: 46020 | B9: 1.1592 | C9: =B9/100 -> 0.011592 | D9: =EXP(-C9*1/252) -> 0.999954 | E9: ='Adj SPY'!E9*'SPY DVD'!C9*1/252*-10 -> -0.316411
A10: 46017 | B10: 1.1551 | C10: =B10/100 -> 0.011551 | D10: =EXP(-C10*1/252) -> 0.99995416 | E10: ='Adj SPY'!E10*'SPY DVD'!C10*1/252*-10 -> -0.31641948
A11: 46015 | B11: 1.1549 | C11: =B11/100 -> 0.011549 | D11: =EXP(-C11*1/252) -> 0.99995417 | E11: ='Adj SPY'!E11*'SPY DVD'!C11*1/252*-10 -> -0.31639677
A12: 46014 | B12: 1.159 | C12: =B12/100 -> 0.01159 | D12: =EXP(-C12*1/252) -> 0.99995401 | E12: ='Adj SPY'!E12*'SPY DVD'!C12*1/252*-10 -> -0.316407
A13: 46013 | B13: 1.1643 | C13: =B13/100 -> 0.011643 | D13: =EXP(-C13*1/252) -> 0.9999538 | E13: ='Adj SPY'!E13*'SPY DVD'!C13*1/252*-10 -> -0.31640777
... A1256: 44207 | B1256: 1.6689 | C1256: =B1256/100 -> 0.016689 | D1256: =EXP(-C1256*1/252) -> 0.99993378 | E1256: ='Adj SPY'!E1256*'SPY DVD'!C1256*1/252*-10 -> -0.25079196

Sheet TLT
A1: Date | B1: Open | C1: High | D1: Low | E1: Close | F1: SMAVG (50) on Close | G1: SMAVG (100) on Close | H1: SMAVG (200) on Close | I1: Volume | J1: SMAVG (15)
A2: 46030 | B2: 87.33 | C2: 87.55 | D2: 87.245 | E2: 87.315 | F2: 88.7839 | G2: 88.9606 | H2: 88.0597 | I2: 19822306 | J2: 31581966
A3: 46029 | B3: 87.84 | C3: 88.005 | D3: 87.48 | E3: 87.79 | F3: 88.8732 | G3: 88.9515 | H3: 88.072 | I3: 39930912 | J3: 33006128
A4: 46028 | B4: 87.15 | C4: 87.34 | D4: 86.9 | E4: 87.28 | F4: 88.9468 | G4: 88.9438 | H4: 88.0865 | I4: 39015180 | J4: 32251518
A5: 46027 | B5: 87.18 | C5: 87.52 | D5: 87.11 | E5: 87.46 | F5: 89.0298 | G5: 88.9477 | H5: 88.1063 | I5: 30178030 | J5: 32785848
A6: 46024 | B6: 87.4 | C6: 87.41 | D6: 87.0201 | E6: 87.03 | F6: 89.1218 | G6: 88.9426 | H6: 88.1249 | I6: 40731252 | J6: 32559226
A7: 46022 | B7: 87.68 | C7: 87.91 | D7: 87.13 | E7: 87.16 | F7: 89.2212 | G7: 88.9462 | H7: 88.1433 | I7: 36500036 | J7: 32966042
A8: 46021 | B8: 87.74 | C8: 88.04 | D8: 87.6744 | E8: 87.86 | F8: 89.309 | G8: 88.9475 | H8: 88.1607 | I8: 25106784 | J8: 32250826
A9: 46020 | B9: 87.95 | C9: 88.0703 | D9: 87.79 | E9: 88.07 | F9: 89.3758 | G9: 88.9456 | H9: 88.1722 | I9: 29399824 | J9: 32727388
A10: 46017 | B10: 88.1 | C10: 88.1699 | D10: 87.6 | E10: 87.74 | F10: 89.4412 | G10: 88.9431 | H10: 88.1851 | I10: 26522734 | J10: 32954604
A11: 46015 | B11: 87.76 | C11: 88.08 | D11: 87.65 | E11: 88.03 | F11: 89.4996 | G11: 88.949 | H11: 88.1957 | I11: 25942006 | J11: 32889186
A12: 46014 | B12: 87.07 | C12: 87.58 | D12: 87.03 | E12: 87.5 | F12: 89.5562 | G12: 88.9493 | H12: 88.2076 | I12: 33624060 | J12: 32711624
A13: 46013 | B13: 87.415 | C13: 87.4574 | D13: 87.25 | E13: 87.36 | F13: 89.6176 | G13: 88.9525 | H13: 88.2253 | I13: 25547134 | J13: 32310398
... A1257: 44204 | B1257: 151.48 | C1257: 151.96 | D1257: 150.66 | E1257: 151.32 | F1257: 157.695 | G1257: 160.204 | H1257: 162.899 | I1257: 13622819 | J1257: 10203540
A1258: 44203 | B1258: 151.79 | C1258: 152.17 | D1258: 151.26 | E1258: 151.81 | F1258: 157.8796 | G1258: 160.3267 | I1258: 14651882 | J1258: 9958964
A1259: 44202 | B1259: 153.82 | C1259: 153.85 | D1259: 152.29 | E1259: 153.16 | F1259: 158.033 | G1259: 160.4404 | I1259: 22827290 | J1259: 9438684
A1260: 44201 | B1260: 156.95 | C1260: 156.95 | D1260: 155.66 | E1260: 156.37 | F1260: 158.13 | G1260: 160.547 | I1260: 10458065 | J1260: 8419256
A1261: 44200 | B1261: 156.67 | C1261: 158.18 | D1261: 156.535 | E1261: 157.54 | F1261: 158.1436 | G1261: 160.6392 | I1261: 13152865 | J1261: 8264458
A1262: 44196 | B1262: 157.46 | C1262: 158.08 | D1262: 157.45 | E1262: 157.73 | F1262: 158.1668 | G1262: 160.7348 | I1262: 7742413 | J1262: 8055942
A1263: 44195 | B1263: 156.82 | C1263: 157.53 | D1263: 156.68 | E1263: 157.5 | F1263: 158.1972 | G1263: 160.8488 | I1263: 9097313 | J1263: 8056451.5
A1264: 44194 | B1264: 156.39 | C1264: 157.29 | D1264: 156.36 | E1264: 157.16 | F1264: 158.2628 | G1264: 160.9725 | I1264: 9030948 | J1264: 7943113.5
A1265: 44193 | B1265: 156.38 | C1265: 157.45 | D1265: 156.095 | E1265: 157.36 | F1265: 158.3474 | G1265: 161.1111 | I1265: 7791093 | J1265: 7962126
A1266: 44189 | B1266: 156.9 | C1266: 157.43 | D1266: 156.85 | E1266: 157.29 | F1266: 158.437 | G1266: 161.2383 | I1266: 3117104 | J1266: 8291696
A1267: 44188 | B1267: 156.62 | C1267: 156.69 | D1267: 155.46 | E1267: 156.67 | F1267: 158.5336 | G1267: 161.381 | I1267: 9266649 | J1267: 8725653
A1268: 44187 | B1268: 157.5634 | C1268: 157.83 | D1268: 157.08 | E1268: 157.76 | F1268: 158.6352 | G1268: 161.5139 | I1268: 7378508 | J1268: 8915515
A1269: 44186 | B1269: 157.2 | C1269: 157.34 | D1269: 156.45 | E1269: 156.95 | F1269: 158.692 | G1269: 161.6463 | I1269: 8988176 | J1269: 9334540
... A1357: 44060 | B1357: 163.97 | C1357: 164.46 | D1357: 163.43 | E1357: 163.59 | F1357: 165.5891 | G1357: 165.5941 | I1357: 6901480 | J1357: 9367280
A1358: 44057 | B1358: 163.81 | C1358: 164.15 | D1358: 163.16 | E1358: 163.18 | F1358: 165.4395 | I1358: 6398178 | J1358: 9316963
A1359: 44056 | B1359: 165.31 | C1359: 165.58 | D1359: 163.165 | E1359: 163.82 | F1359: 165.3205 | I1359: 12744712 | J1359: 9391807
A1360: 44055 | B1360: 165.7 | C1360: 166.065 | D1360: 164.99 | E1360: 165.59 | F1360: 165.2349 | I1360: 11745839 | J1360: 9240280
A1361: 44054 | B1361: 167.17 | C1361: 167.49 | D1361: 165.875 | E1361: 167.105 | F1361: 165.1569 | I1361: 19234202 | J1361: 8896696
A1362: 44053 | B1362: 170.22 | C1362: 170.25 | D1362: 169.07 | E1362: 169.12 | F1362: 165.0604 | I1362: 6408461 | J1362: 8178090
A1363: 44050 | B1363: 171.28 | C1363: 171.5 | D1363: 169.58 | E1363: 169.88 | F1363: 164.9498 | I1363: 8176856 | J1363: 8211360.5
A1364: 44049 | B1364: 171.38 | C1364: 172.25 | D1364: 170.62 | E1364: 171.02 | F1364: 164.8008 | I1364: 9481800 | J1364: 8236248
A1365: 44048 | B1365: 170.06 | C1365: 170.56 | D1365: 169.69 | E1365: 170.07 | F1365: 164.641 | I1365: 6954183 | J1365: 8211286.5
A1366: 44047 | B1366: 170.83 | C1366: 171.58 | D1366: 170.72 | E1366: 171.57 | F1366: 164.5062 | I1366: 9878888 | J1366: 8270380
A1367: 44046 | B1367: 169.24 | C1367: 169.99 | D1367: 168.97 | E1367: 169.95 | F1367: 164.3858 | I1367: 9067756 | J1367: 8368096.5
A1368: 44043 | B1368: 170.15 | C1368: 171.4554 | D1368: 169.94 | E1368: 171 | F1368: 164.278 | I1368: 8886264 | J1368: 8300513.5
A1369: 44042 | B1369: 171.05 | C1369: 171.26 | D1369: 170.75 | E1369: 171.11 | F1369: 164.141 | I1369: 9376128 | J1369: 8273321
... A1407: 43987 | B1407: 154.61 | C1407: 156.16 | D1407: 153.16 | E1407: 156.11 | F1407: 165.599 | I1407: 17778548 | J1407: 10718068
...

Sheet Adj TLT
A1: Date | B1: Open | C1: High | D1: Low | E1: Close | F1: Volume | G1: Dividends | H1: Adj Factor DVD | I1: Adj. Open | J1: Adj. High | K1: Adj. Low | L1: Adj. Close
A2: 46030 | B2: 87.33 | C2: 87.55 | D2: 87.245 | E2: 87.315 | F2: 19822306 | G2: =IFERROR(VLOOKUP(A2,'TLT DVD'!$A$1:$D$1249,2,FALSE),0) -> 0 | H2: =IFERROR(VLOOKUP(A2,'TLT DVD'!$A$1:$D$1249,4,FALSE),0) -> 1 | I2: =IFERROR(B2*$H2,0) -> 87.33 | J2: =IFERROR(C2*$H2,0) -> 87.55 | K2: =IFERROR(D2*$H2,0) -> 87.245 | L2: =IFERROR(E2*$H2,0) -> 87.315
A3: 46029 | B3: 87.84 | C3: 88.005 | D3: 87.48 | E3: 87.79 | F3: 39930912 | G3: =IFERROR(VLOOKUP(A3,'TLT DVD'!$A$1:$D$1249,2,FALSE),0) -> 0 | H3: 1 | I3: =IFERROR(B3*$H3,0) -> 87.84 | J3: =IFERROR(C3*$H3,0) -> 88.005 | K3: =IFERROR(D3*$H3,0) -> 87.48 | L3: =IFERROR(E3*$H3,0) -> 87.79
A4: 46028 | B4: 87.15 | C4: 87.34 | D4: 86.9 | E4: 87.28 | F4: 39015180 | G4: =IFERROR(VLOOKUP(A4,'TLT DVD'!$A$1:$D$1249,2,FALSE),0) -> 0 | H4: 1 | I4: =IFERROR(B4*$H4,0) -> 87.15 | J4: =IFERROR(C4*$H4,0) -> 87.34 | K4: =IFERROR(D4*$H4,0) -> 86.9 | L4: =IFERROR(E4*$H4,0) -> 87.28
A5: 46027 | B5: 87.18 | C5: 87.52 | D5: 87.11 | E5: 87.46 | F5: 30178030 | G5: =IFERROR(VLOOKUP(A5,'TLT DVD'!$A$1:$D$1249,2,FALSE),0) -> 0 | H5: 1 | I5: =IFERROR(B5*$H5,0) -> 87.18 | J5: =IFERROR(C5*$H5,0) -> 87.52 | K5: =IFERROR(D5*$H5,0) -> 87.11 | L5: =IFERROR(E5*$H5,0) -> 87.46
A6: 46024 | B6: 87.4 | C6: 87.41 | D6: 87.0201 | E6: 87.03 | F6: 40731252 | G6: =IFERROR(VLOOKUP(A6,'TLT DVD'!$A$1:$D$1249,2,FALSE),0) -> 0 | H6: 1 | I6: =IFERROR(B6*$H6,0) -> 87.4 | J6: =IFERROR(C6*$H6,0) -> 87.41 | K6: =IFERROR(D6*$H6,0) -> 87.0201 | L6: =IFERROR(E6*$H6,0) -> 87.03
A7: 46022 | B7: 87.68 | C7: 87.91 | D7: 87.13 | E7: 87.16 | F7: 36500036 | G7: =IFERROR(VLOOKUP(A7,'TLT DVD'!$A$1:$D$1249,2,FALSE),0) -> 0 | H7: 1 | I7: =IFERROR(B7*$H7,0) -> 87.68 | J7: =IFERROR(C7*$H7,0) -> 87.91 | K7: =IFERROR(D7*$H7,0) -> 87.13 | L7: =IFERROR(E7*$H7,0) -> 87.16
A8: 46021 | B8: 87.74 | C8: 88.04 | D8: 87.6744 | E8: 87.86 | F8: 25106784 | G8: =IFERROR(VLOOKUP(A8,'TLT DVD'!$A$1:$D$1249,2,FALSE),0) -> 0 | H8: 1 | I8: =IFERROR(B8*$H8,0) -> 87.74 | J8: =IFERROR(C8*$H8,0) -> 88.04 | K8: =IFERROR(D8*$H8,0) -> 87.6744 | L8: =IFERROR(E8*$H8,0) -> 87.86
A9: 46020 | B9: 87.95 | C9: 88.0703 | D9: 87.79 | E9: 88.07 | F9: 29399824 | G9: =IFERROR(VLOOKUP(A9,'TLT DVD'!$A$1:$D$1249,2,FALSE),0) -> 0 | H9: 1 | I9: =IFERROR(B9*$H9,0) -> 87.95 | J9: =IFERROR(C9*$H9,0) -> 88.0703 | K9: =IFERROR(D9*$H9,0) -> 87.79 | L9: =IFERROR(E9*$H9,0) -> 88.07
A10: 46017 | B10: 88.1 | C10: 88.1699 | D10: 87.6 | E10: 87.74 | F10: 26522734 | G10: =IFERROR(VLOOKUP(A10,'TLT DVD'!$A$1:$D$1249,2,FALSE),0) -> 4.6834 | H10: =IFERROR(VLOOKUP(A10,'TLT DVD'!$A$1:$D$1249,4,FALSE),0) -> 0.99981417 | I10: =IFERROR(B10*$H10,0) -> 88.083628 | J10: =IFERROR(C10*$H10,0) -> 88.153515 | K10: =IFERROR(D10*$H10,0) -> 87.583721 | L10: =IFERROR(E10*$H10,0) -> 87.723695
A11: 46015 | B11: 87.76 | C11: 88.08 | D11: 87.65 | E11: 88.03 | F11: 25942006 | G11: =IFERROR(VLOOKUP(A11,'TLT DVD'!$A$1:$D$1249,2,FALSE),0) -> 4.668 | H11: =IFERROR(VLOOKUP(A11,'TLT DVD'!$A$1:$D$1249,4,FALSE),0) -> 0.99981478 | I11: =IFERROR(B11*$H11,0) -> 87.743745 | J11: =IFERROR(C11*$H11,0) -> 88.063686 | K11: =IFERROR(D11*$H11,0) -> 87.633765 | L11: =IFERROR(E11*$H11,0) -> 88.013695
A12: 46014 | B12: 87.07 | C12: 87.58 | D12: 87.03 | E12: 87.5 | F12: 33624060 | G12: =IFERROR(VLOOKUP(A12,'TLT DVD'!$A$1:$D$1249,2,FALSE),0) -> 4.6963 | H12: =IFERROR(VLOOKUP(A12,'TLT DVD'!$A$1:$D$1249,4,FALSE),0) -> 0.99981366 | I12: =IFERROR(B12*$H12,0) -> 87.053775 | J12: =IFERROR(C12*$H12,0) -> 87.56368 | K12: =IFERROR(D12*$H12,0) -> 87.013783 | L12: =IFERROR(E12*$H12,0) -> 87.483695
A13: 46013 | B13: 87.415 | C13: 87.4574 | D13: 87.25 | E13: 87.36 | F13: 25547134 | G13: =IFERROR(VLOOKUP(A13,'TLT DVD'!$A$1:$D$1249,2,FALSE),0) -> 4.7038 | H13: =IFERROR(VLOOKUP(A13,'TLT DVD'!$A$1:$D$1249,4,FALSE),0) -> 0.99981336 | I13: =IFERROR(B13*$H13,0) -> 87.398685 | J13: =IFERROR(C13*$H13,0) -> 87.441077 | K13: =IFERROR(D13*$H13,0) -> 87.233716 | L13: =IFERROR(E13*$H13,0) -> 87.343695
A14: 46010 | B14: 87.605 | C14: 87.76 | D14: 87.41 | E14: 87.55 | F14: 37858080 | G14: =IFERROR(VLOOKUP(A14,'TLT DVD'!$A$1:$D$1249,2,FALSE),0) -> 4.6936 | H14: =IFERROR(VLOOKUP(A14,'TLT DVD'!$A$1:$D$1249,4,FALSE),0) -> 0.99981376 | I14: =IFERROR(B14*$H14,0) -> 87.588685 | J14: =IFERROR(C14*$H14,0) -> 87.743656 | K14: =IFERROR(D14*$H14,0) -> 87.393721 | L14: =IFERROR(E14*$H14,0) -> 87.533695
A15: 46009 | B15: 88.13 | C15: 88.38 | D15: 88.07 | E15: 88.22 | F15: 39048892 | G15: =IFERROR(VLOOKUP(A15,'TLT DVD'!$A$1:$D$1249,2,FALSE),0) -> 4.658 | H15: =IFERROR(VLOOKUP(A15,'TLT DVD'!$A$1:$D$1249,4,FALSE),0) -> 0.99981518 | I15: =IFERROR(B15*$H15,0) -> 88.113711 | J15: =IFERROR(C15*$H15,0) -> 88.363665 | K15: =IFERROR(D15*$H15,0) -> 88.053723 | L15: =IFERROR(E15*$H15,0) -> 88.203695
A16: 46008 | B16: 87.625 | C16: 87.9856 | D16: 87.5801 | E16: 87.8 | F16: 24668304 | G16: =IFERROR(VLOOKUP(A16,'TLT DVD'!$A$1:$D$1249,2,FALSE),0) -> 4.3824 | H16: =IFERROR(VLOOKUP(A16,'TLT DVD'!$A$1:$D$1249,4,FALSE),0) -> 0.99982611 | I16: =IFERROR(B16*$H16,0) -> 87.609763 | J16: =IFERROR(C16*$H16,0) -> 87.9703 | K16: =IFERROR(D16*$H16,0) -> 87.564871 | L16: =IFERROR(E16*$H16,0) -> 87.784732
A17: 46007 | B17: 87.185 | C17: 87.92 | D17: 87.17 | E17: 87.88 | F17: 41018680 | G17: =IFERROR(VLOOKUP(A17,'TLT DVD'!$A$1:$D$1249,2,FALSE),0) -> 4.3784 | H17: =IFERROR(VLOOKUP(A17,'TLT DVD'!$A$1:$D$1249,4,FALSE),0) -> 0.99982627 | I17: =IFERROR(B17*$H17,0) -> 87.169853 | J17: =IFERROR(C17*$H17,0) -> 87.904726 | K17: =IFERROR(D17*$H17,0) -> 87.154856 | L17: =IFERROR(E17*$H17,0) -> 87.864733
A18: 46006 | B18: 87.715 | C18: 87.88 | D18: 87.39 | E18: 87.4 | F18: 28611788 | G18: =IFERROR(VLOOKUP(A18,'TLT DVD'!$A$1:$D$1249,2,FALSE),0) -> 4.4025 | H18: =IFERROR(VLOOKUP(A18,'TLT DVD'!$A$1:$D$1249,4,FALSE),0) -> 0.99982531 | I18: =IFERROR(B18*$H18,0) -> 87.699677 | J18: =IFERROR(C18*$H18,0) -> 87.864648 | K18: =IFERROR(D18*$H18,0) -> 87.374734 | L18: =IFERROR(E18*$H18,0) -> 87.384732
A19: 46003 | B19: 87.375 | C19: 87.495 | D19: 87.19 | E19: 87.34 | F19: 47030120 | G19: =IFERROR(VLOOKUP(A19,'TLT DVD'!$A$1:$D$1249,2,FALSE),0) -> 4.4055 | H19: =IFERROR(VLOOKUP(A19,'TLT DVD'!$A$1:$D$1249,4,FALSE),0) -> 0.99982519 | I19: =IFERROR(B19*$H19,0) -> 87.359726 | J19: =IFERROR(C19*$H19,0) -> 87.479705 | K19: =IFERROR(D19*$H19,0) -> 87.174759 | L19: =IFERROR(E19*$H19,0) -> 87.324732
A20: 46002 | B20: 88.69 | C20: 88.83 | D20: 88.16 | E20: 88.19 | F20: 26778686 | G20: =IFERROR(VLOOKUP(A20,'TLT DVD'!$A$1:$D$1249,2,FALSE),0) -> 4.3631 | H20: =IFERROR(VLOOKUP(A20,'TLT DVD'!$A$1:$D$1249,4,FALSE),0) -> 0.99982688 | I20: =IFERROR(B20*$H20,0) -> 88.674646 | J20: =IFERROR(C20*$H20,0) -> 88.814621 | K20: =IFERROR(D20*$H20,0) -> 88.144737 | L20: =IFERROR(E20*$H20,0) -> 88.174732
A21: 46001 | B21: 88 | C21: 88.52 | D21: 87.855 | E21: 88.31 | F21: 46833512 | G21: =IFERROR(VLOOKUP(A21,'TLT DVD'!$A$1:$D$1249,2,FALSE),0) -> 4.3571 | H21: =IFERROR(VLOOKUP(A21,'TLT DVD'!$A$1:$D$1249,4,FALSE),0) -> 0.99982711 | I21: =IFERROR(B21*$H21,0) -> 87.984786 | J21: =IFERROR(C21*$H21,0) -> 88.504696 | K21: =IFERROR(D21*$H21,0) -> 87.839811 | L21: =IFERROR(E21*$H21,0) -> 88.294732
... A1456: 43916 | B1456: 163.995 | C1456: 165.68 | D1456: 162.27 | E1456: 163.34 | F1456: 10576587 | G1456: =IFERROR(VLOOKUP(A1456,'TLT DVD'!$A$1:$D$1249,2,FALSE),0) -> 0 | H1456: =IFERROR(VLOOKUP(A1456,'TLT DVD'!$A$1:$D$1249,4,FALSE),0) -> 0 | I1456: =IFERROR(B1456*$H1456,0) -> 0 | J1456: =IFERROR(C1456*$H1456,0) -> 0 | K1456: =IFERROR(D1456*$H1456,0) -> 0 | L1456: =IFERROR(E1456*$H1456,0) -> 0

Sheet TLT DVD
A1: Date | B1: TLT US Equity - Dividend Indicated Yld - Gross | C1: Percentage | D1: adj factor | E1: Dividends paid
A2: 46030 | D2: =EXP(-B2*1/252) -> 1 | E2: ='Adj TLT'!E2*'TLT DVD'!C2*1/252*-25 -> 0
